xml
Copy code
<?xml version="1.0"?>
<robot name="excavator">

  <link name="base_link">
    <inertial>
      <mass value="100.0"/>
      <origin rpy="0 0 0" xyz="0 0 0"/>
      <inertia ixx="100.0" ixy="0.0" ixz="0.0" iyy="100.0" iyz="0.0" izz="100.0"/>
    </inertial>
    <visual>
      <geometry>
        <box size="1.0 1.0 1.0"/>
      </geometry>
      <origin rpy="0 0 0" xyz="0 0 0"/>
      <material name="red">
        <color rgba="1 0 0 1"/>
      </material>
    </visual>
  </link>

  <joint name="base_joint" type="revolute">
    <parent link="world"/>
    <child link="base_link"/>
    <origin rpy="0 0 0" xyz="0 0 0"/>
    <axis xyz="0 0 1"/>
    <limit effort="100.0" lower="-1.57" upper="1.57" velocity="1.0"/>
  </joint>

  <link name="arm_link">
    <inertial>
      <mass value="50.0"/>
      <origin rpy="0 0 0" xyz="0 0 2"/>
      <inertia ixx="50.0" ixy="0.0" ixz="0.0" iyy="50.0" iyz="0.0" izz="50.0"/>
    </inertial>
    <visual>
      <geometry>
        <cylinder length="2" radius="0.5"/>
      </geometry>
      <origin rpy="0 0 0" xyz="0 0 1"/>
      <material name="blue">
        <color rgba="0 0 1 1"/>
      </material>
    </visual>
  </link>

  <joint name="arm_joint" type="revolute">
    <parent link="base_link"/>
    <child link="arm_link"/>
    <origin rpy="0 0 0" xyz="0 0 1"/>
    <axis xyz="0 1 0"/>
    <limit effort="50.0" lower="-1.57" upper="1.57" velocity="1.0"/>
  </joint>
  
</robot>